Workbook

Sheet FINAL
A1: KEY | B1: T_date | C1: P_date | D1: T_details | E1: T_amount | F1: Cal_ind | G1: T_amount_abs | H1: Card_type | I1: T_type | J1: T_agency | K1: Fin_Type | L1: CC_Bill_Status | M1: EMI_Ind | N1: B_Month | O1: Remark
A2: =B2&C2&G2&H2&I2&J2 -> 437034370350CURRENTWITHDRAWSELF | B2: 43703 | C2: =B2 -> 43703 | D2: ATM CASH WITHDRAWAL,923816758781,4612 758781,COMM. BANK OF QATAR DOHA,4342041934720023 26/08 19.07 | E2: -50 | F2: 1 | G2: =ABS(E2)*F2 -> 50 | H2: CURRENT | I2: WITHDRAW | J2: SELF | K2: DEBIT | L2: NA | N2: =MONTH(C2) -> 8
A3: =B3&C3&G3&H3&I3&J3 -> 437034370310CURRENTSERVICEBANK | B3: 43703 | C3: =B3 -> 43703 | D3: SELF CHEQUE BOOK FEE,637024429596 | E3: -10 | F3: 1 | G3: =ABS(E3)*F3 -> 10 | H3: CURRENT | I3: SERVICE | J3: BANK | K3: DEBIT | L3: NA | N3: =MONTH(C3) -> 8
A4: =B4&C4&G4&H4&I4&J4 -> 437034370350CURRENTLOANFRIEND | B4: 43703 | C4: =B4 -> 43703 | D4: TRANSFER - CREDIT,260819113085,Transfer From 4010-512145-001,AKSHIT WALIA | E4: 50 | F4: 1 | G4: =ABS(E4)*F4 -> 50 | H4: CURRENT | I4: LOAN | J4: FRIEND | K4: CREDIT | L4: NA | N4: =MONTH(C4) -> 8
A5: =B5&C5&G5&H5&I5&J5 -> 437034370350CURRENTLOANFRIEND | B5: 43703 | C5: =B5 -> 43703 | D5: TRANSFER - CREDIT,260819113069,Transfer From 4010-512145-001,AKSHIT WALIA | E5: 50 | F5: 1 | G5: =ABS(E5)*F5 -> 50 | H5: CURRENT | I5: LOAN | J5: FRIEND | K5: CREDIT | L5: NA | N5: =MONTH(C5) -> 8
A6: =B6&C6&G6&H6&I6&J6 -> 437034370328CURRENTFOODCAFÉ/REST. | B6: 43703 | C6: =B6 -> 43703 | D6: NAPS PURCHASE,000001049025,4018 016772 72240402,HAREESONA DOHA,4342041934720023 26/08 19.30,63409000000 | E6: -28 | F6: 1 | G6: =ABS(E6)*F6 -> 28 | H6: CURRENT | I6: FOOD | J6: CAFÉ/REST. | K6: DEBIT | L6: NA | N6: =MONTH(C6) -> 8
A7: =B7&C7&G7&H7&I7&J7 -> 4370443704500CURRENTWITHDRAWSELF | B7: 43704 | C7: =B7 -> 43704 | D7: NAPS ATM,923907875302,4018 011576 IQ000136,IBQ QATAR AIRWAYS DOHA,4342041934720023 27/08 10.49,63402000000 | E7: -500 | F7: 1 | G7: =ABS(E7)*F7 -> 500 | H7: CURRENT | I7: WITHDRAW | J7: SELF | K7: DEBIT | L7: NA | N7: =MONTH(C7) -> 8
A8: =B8&C8&G8&H8&I8&J8 -> 43704437042559CURRENTTRANSFERINDIA | B8: 43704 | C8: =B8 -> 43704 | D8: TELEX TRANSFER,270819013421,family,Vineet Kumar Saraswat | E8: -2559 | F8: 1 | G8: =ABS(E8)*F8 -> 2559 | H8: CURRENT | I8: TRANSFER | J8: INDIA | K8: DEBIT | L8: NA | N8: =MONTH(C8) -> 8
A9: =B9&C9&G9&H9&I9&J9 -> 437044370415CURRENTSERVICEBANK | B9: 43704 | C9: =B9 -> 43704 | D9: TELEX CHARGE,270819013421,Telex Transfer Charges | E9: -15 | F9: 1 | G9: =ABS(E9)*F9 -> 15 | H9: CURRENT | I9: SERVICE | J9: BANK | K9: DEBIT | L9: NA | N9: =MONTH(C9) -> 8
A10: =B10&C10&G10&H10&I10&J10 -> 437044370418244CURRENTSALARYQATAR AIR | B10: 43704 | C10: =B10 -> 43704 | D10: SALARY TRANSFER,CDD 90827H005601,QCH4487250990000 QAR,QATAR AIRWAYS,2/SALA | E10: 12929 | F10: 1 | G10: 18244 | H10: CURRENT | I10: SALARY | J10: QATAR AIR | K10: CREDIT | L10: NA | N10: =MONTH(C10) -> 8
A11: =B11&C11&G11&H11&I11&J11 -> 43704437045315CURRENTRENTQATAR AIR | B11: 43704 | C11: =B11 -> 43704 | D11: COMPANY ACCOMODATION ALLOWANCES | E11: 5315 | F11: 1 | G11: =ABS(E11)*F11 -> 5315 | H11: CURRENT | I11: RENT | J11: QATAR AIR | K11: DEBIT | L11: NA | N11: =MONTH(C11) -> 8
A12: =B12&C12&G12&H12&I12&J12 -> 43704437092000CURRENTRENTCAP ONE | B12: 43704 | C12: 43709 | D12: NAPS ATM,923907875302,4018 011576 IQ000136,IBQ QATAR AIRWAYS DOHA,4342041934720023 27/08 10.49,63402000000-KARAH MAA ADVANCE TO CAP ONE | E12: -2000 | F12: 1 | G12: 2000 | H12: CURRENT | I12: RENT | J12: CAP ONE | K12: DEBIT | L12: NA | N12: =MONTH(C12) -> 9
A13: =B13&C13&G13&H13&I13&J13 -> 43704437094500CURRENTRENTCAP ONE | B13: 43704 | C13: 43709 | D13: NAPS ATM,923907875302,4018 011576 IQ000136,IBQ QATAR AIRWAYS DOHA,4342041934720023 27/08 10.49,63402000000-RENT SECURITY TO CAP ONE | E13: -4500 | F13: 1 | G13: 4500 | H13: CURRENT | I13: RENT | J13: CAP ONE | K13: DEBIT | L13: NA | N13: =MONTH(C13) -> 9
A14: =B14&C14&G14&H14&I14&J14 -> 43704437041092CURRENTLOANFRIEND | B14: 43704 | C14: =B14 -> 43704 | D14: TRANSFER - DEBIT,270819110844,helping amount,Akshit Walia | E14: -1092 | F14: 1 | G14: =ABS(E14)*F14 -> 1092 | H14: CURRENT | I14: LOAN | J14: FRIEND | K14: DEBIT | L14: NA | N14: =MONTH(C14) -> 8
A15: =B15&C15&G15&H15&I15&J15 -> 437054370515CURRENTSERVICEBANK | B15: 43705 | C15: =B15 -> 43705 | D15: COMMISSION/FEE,4700-193472-001,Re-Issuance of new cheque book-RIB | E15: -15 | F15: 1 | G15: =ABS(E15)*F15 -> 15 | H15: CURRENT | I15: SERVICE | J15: BANK | K15: DEBIT | L15: NA | N15: =MONTH(C15) -> 8
A16: =B16&C16&G16&H16&I16&J16 -> 437094370915CURRENTSERVICEBANK | B16: 43709 | C16: =B16 -> 43709 | D16: CREDIT,270819013421,BAW-TT Charge Refund | E16: 15 | F16: 1 | G16: =ABS(E16)*F16 -> 15 | H16: CURRENT | I16: SERVICE | J16: BANK | K16: CREDIT | L16: NA | N16: =MONTH(C16) -> 9
A17: =B17&C17&G17&H17&I17&J17 -> 437094370925CURRENTFOODQATAR AIR | B17: 43709 | C17: =B17 -> 43709 | D17: NAPS PURCHASE,000001048059,4018 007412 82491201,THE COFFEE SHOP QR TOWDOHA,4342041934720023 01/09 11.47,63409000000 | E17: -25 | F17: 1 | G17: =ABS(E17)*F17 -> 25 | H17: CURRENT | I17: FOOD | J17: QATAR AIR | K17: DEBIT | L17: NA | N17: =MONTH(C17) -> 9
A18: =B18&C18&G18&H18&I18&J18 -> 4371343718500MASTER CCVISAMINISTERY | B18: 43713 | C18: 43718 | D18: MINISTER OF FOREIGN AF DOHA QAT AUTH NO. 047645 | E18: 500 | F18: 1 | G18: =ABS(E18)*F18 -> 500 | H18: MASTER CC | I18: VISA | J18: MINISTERY | K18: DEBIT | L18: BILLED | N18: =MONTH(C18) -> 9
A19: =B19&C19&G19&H19&I19&J19 -> 43713437158MASTER CCTRANSPORTCAREEM | B19: 43713 | C19: 43715 | D19: CAREEM NETWORKS FZ LLC DUBAI ARE AUTH NO. 091262 | E19: 8 | F19: 1 | G19: =ABS(E19)*F19 -> 8 | H19: MASTER CC | I19: TRANSPORT | J19: CAREEM | K19: DEBIT | L19: BILLED | N19: =MONTH(C19) -> 9
A20: =B20&C20&G20&H20&I20&J20 -> 43714437168MASTER CCTRANSPORTCAREEM | B20: 43714 | C20: 43716 | D20: CAREEM NETWORKS FZ LLC DUBAI ARE AUTH NO. 071417 | E20: 8 | F20: 1 | G20: =ABS(E20)*F20 -> 8 | H20: MASTER CC | I20: TRANSPORT | J20: CAREEM | K20: DEBIT | L20: BILLED | N20: =MONTH(C20) -> 9
A21: =B21&C21&G21&H21&I21&J21 -> 437144371834MASTER CCFOODCAFÉ/REST. | B21: 43714 | C21: 43718 | D21: CAFE TASSE -SOUQ WAQEF DOHA QAT AUTH NO. 024771 | E21: 34 | F21: 1 | G21: =ABS(E21)*F21 -> 34 | H21: MASTER CC | I21: FOOD | J21: CAFÉ/REST. | K21: DEBIT | L21: BILLED | N21: =MONTH(C21) -> 9
A22: =B22&C22&G22&H22&I22&J22 -> 437154371835MASTER CCTRANSPORTCAREEM | B22: 43715 | C22: 43718 | D22: CAREEM NETWORKS FZ LLC DUBAI ARE AUTH NO. 052270 | E22: 35 | F22: 1 | G22: =ABS(E22)*F22 -> 35 | H22: MASTER CC | I22: TRANSPORT | J22: CAREEM | K22: DEBIT | L22: BILLED | N22: =MONTH(C22) -> 9
A23: =B23&C23&G23&H23&I23&J23 -> 437184372015MASTER CCFOODQATAR AIR | B23: 43718 | C23: 43720 | D23: THE COFFEE SHOP QR TOW DOHA QAT AUTH NO. 098436 | E23: 15 | F23: 1 | G23: =ABS(E23)*F23 -> 15 | H23: MASTER CC | I23: FOOD | J23: QATAR AIR | K23: DEBIT | L23: BILLED | N23: =MONTH(C23) -> 9
A24: =B24&C24&G24&H24&I24&J24 -> 437184372035MASTER CCFOODQATAR AIR | B24: 43718 | C24: 43720 | D24: QATAR AIR DOHA QAT AUTH NO. 018563 | E24: 35 | F24: 1 | G24: =ABS(E24)*F24 -> 35 | H24: MASTER CC | I24: FOOD | J24: QATAR AIR | K24: DEBIT | L24: BILLED | N24: =MONTH(C24) -> 9
A25: =B25&C25&G25&H25&I25&J25 -> 437194372112MASTER CCFOODQATAR AIR | B25: 43719 | C25: 43721 | D25: THE COFFEE SHOP QR TOW DOHA QAT AUTH NO. 058426 | E25: 12 | F25: 1 | G25: =ABS(E25)*F25 -> 12 | H25: MASTER CC | I25: FOOD | J25: QATAR AIR | K25: DEBIT | L25: BILLED | N25: =MONTH(C25) -> 9
A26: =B26&C26&G26&H26&I26&J26 -> 4372043720500CURRENTWITHDRAWSELF | B26: 43720 | C26: =B26 -> 43720 | D26: NAPS ATM,925505987099,4018 013997 IQ000148,QATAR AIRWAYS BRANCH 2DOHA,4342041934720023 12/09 08.48,63402000000 | E26: -500 | F26: 1 | G26: =ABS(E26)*F26 -> 500 | H26: CURRENT | I26: WITHDRAW | J26: SELF | K26: DEBIT | L26: NA | N26: =MONTH(C26) -> 9
A27: =B27&C27&G27&H27&I27&J27 -> 437204372511MASTER CCFOODQATAR AIR | B27: 43720 | C27: 43725 | D27: THE COFFEE SHOP QR TOW DOHA QAT AUTH NO. 089552 | E27: 11 | F27: 1 | G27: =ABS(E27)*F27 -> 11 | H27: MASTER CC | I27: FOOD | J27: QATAR AIR | K27: DEBIT | L27: BILLED | N27: =MONTH(C27) -> 9
A28: =B28&C28&G28&H28&I28&J28 -> 437204372512MASTER CCFOODQATAR AIR | B28: 43720 | C28: 43725 | D28: THE COFFEE SHOP QR TOW DOHA QAT AUTH NO. 024301 | E28: 12 | F28: 1 | G28: =ABS(E28)*F28 -> 12 | H28: MASTER CC | I28: FOOD | J28: QATAR AIR | K28: DEBIT | L28: BILLED | N28: =MONTH(C28) -> 9
A29: =B29&C29&G29&H29&I29&J29 -> 437204372535MASTER CCFOODQATAR AIR | B29: 43720 | C29: 43725 | D29: QATAR AIR DOHA QAT AUTH NO. 005171 | E29: 35 | F29: 1 | G29: =ABS(E29)*F29 -> 35 | H29: MASTER CC | I29: FOOD | J29: QATAR AIR | K29: DEBIT | L29: BILLED | N29: =MONTH(C29) -> 9
A30: =B30&C30&G30&H30&I30&J30 -> 43720437222MASTER CCTRANSPORTCAREEM | B30: 43720 | C30: 43722 | D30: CAREEM NETWORKS FZ LLC DUBAI ARE AUTH NO. 036073 | E30: 2 | F30: 1 | G30: =ABS(E30)*F30 -> 2 | H30: MASTER CC | I30: TRANSPORT | J30: CAREEM | K30: DEBIT | L30: BILLED | N30: =MONTH(C30) -> 9
A31: =B31&C31&G31&H31&I31&J31 -> 437214372254.7DINERSGROCERYLULU | B31: 43721 | C31: 43722 | D31: LULU EXPRESS TRADING COMP DOHA 634 AUTH NO. 028120 | E31: 54.7 | F31: 1 | G31: =ABS(E31)*F31 -> 54.7 | H31: DINERS | I31: GROCERY | J31: LULU | K31: DEBIT | L31: BILLED | N31: =MONTH(C31) -> 9
A32: =B32&C32&G32&H32&I32&J32 -> 437214372233DINERSFOODCAFÉ/REST. | B32: 43721 | C32: 43722 | D32: KAILASH PARBAT RESTAURANT DOHA 634 AUTH NO. 067662 | E32: 33 | F32: 1 | G32: =ABS(E32)*F32 -> 33 | H32: DINERS | I32: FOOD | J32: CAFÉ/REST. | K32: DEBIT | L32: BILLED | N32: =MONTH(C32) -> 9
A33: =B33&C33&G33&H33&I33&J33 -> 437234372515.71DINERSTRANSPORTUBER | B33: 43723 | C33: 43725 | D33: UBERBV UBER TRIP HELP.UBE HELP.UBER.COM 528 AUTH NO. 072654 | E33: 15.71 | F33: 1 | G33: =ABS(E33)*F33 -> 15.71 | H33: DINERS | I33: TRANSPORT | J33: UBER | K33: DEBIT | L33: BILLED | N33: =MONTH(C33) -> 9
A34: =B34&C34&G34&H34&I34&J34 -> 437234372513MASTER CCFOODQATAR AIR | B34: 43723 | C34: 43725 | D34: THE COFFEE SHOP QR TOW DOHA QAT AUTH NO. 007288 | E34: 13 | F34: 1 | G34: =ABS(E34)*F34 -> 13 | H34: MASTER CC | I34: FOOD | J34: QATAR AIR | K34: DEBIT | L34: BILLED | N34: =MONTH(C34) -> 9
A35: =B35&C35&G35&H35&I35&J35 -> 437244372638MASTER CCFOODQATAR AIR | B35: 43724 | C35: 43726 | D35: THE COFFEE SHOP QR TOW DOHA QAT AUTH NO. 064146 | E35: 38 | F35: 1 | G35: =ABS(E35)*F35 -> 38 | H35: MASTER CC | I35: FOOD | J35: QATAR AIR | K35: DEBIT | L35: BILLED | N35: =MONTH(C35) -> 9
A36: =B36&C36&G36&H36&I36&J36 -> 437284373244.25MASTER CCGROCERYGRANDMART | B36: 43728 | C36: 43732 | D36: GRAND MART SUPERMARKET DOHA QAT AUTH NO. 006245 | E36: 44.25 | F36: 1 | G36: =ABS(E36)*F36 -> 44.25 | H36: MASTER CC | I36: GROCERY | J36: GRANDMART | K36: DEBIT | L36: BILLED | N36: =MONTH(C36) -> 9
A37: =B37&C37&G37&H37&I37&J37 -> 4372943730333.17DINERSSHOPPINGLULU | B37: 43729 | C37: 43730 | D37: LULU HYPERMARKET DOHA 634 AUTH NO. 007898 | E37: 333.17 | F37: 1 | G37: =ABS(E37)*F37 -> 333.17 | H37: DINERS | I37: SHOPPING | J37: LULU | K37: DEBIT | L37: BILLED | M37: 1 | N37: =MONTH(C37) -> 9
A38: =B38&C38&G38&H38&I38&J38 -> 437294373025DINERSGROCERYLULU | B38: 43729 | C38: 43730 | D38: LULU HYPERMARKET DOHA 634 AUTH NO. 055996 | E38: 25 | F38: 1 | G38: =ABS(E38)*F38 -> 25 | H38: DINERS | I38: GROCERY | J38: LULU | K38: DEBIT | L38: BILLED | N38: =MONTH(C38) -> 9
A39: =B39&C39&G39&H39&I39&J39 -> 437294373210MASTER CCTRANSPORTCAREEM | B39: 43729 | C39: 43732 | D39: CAREEM NETWORKS FZ LLC DUBAI ARE AUTH NO. 081642 | E39: 10 | F39: 1 | G39: =ABS(E39)*F39 -> 10 | H39: MASTER CC | I39: TRANSPORT | J39: CAREEM | K39: DEBIT | L39: BILLED | N39: =MONTH(C39) -> 9
A40: =B40&C40&G40&H40&I40&J40 -> 43729437328MASTER CCTRANSPORTCAREEM | B40: 43729 | C40: 43732 | D40: CAREEM NETWORKS FZ LLC DUBAI ARE AUTH NO. 047498 | E40: 8 | F40: 1 | G40: =ABS(E40)*F40 -> 8 | H40: MASTER CC | I40: TRANSPORT | J40: CAREEM | K40: DEBIT | L40: BILLED | N40: =MONTH(C40) -> 9
...

Sheet stock
A1: stock_name | B1: stock_ticker | C1: stock_pur_date | D1: stock_units | E1: stock_buy_price | F1: stock_broker | G1: stock_sector
A2: ASIANPAINT | B2: ASIANPAINT.NS | C2: 44623 | D2: 11 | E2: 2763.03 | F2: ZERODHA | G2: Chemicals
A3: ASTRAL | B3: ASTRAL.NS | C3: 44932 | D3: 19 | E3: 1669.85 | F3: ZERODHA | G3: Plastics - Tubes/Pipes
A4: CDSL | B4: CDSL.NS | C4: 44593 | D4: 50 | E4: 644.61 | F4: ZERODHA | G4: Banking & Financial Services
A5: HINDUNILVR | B5: HINDUNILVR.NS | C5: 44932 | D5: 8 | E5: 2548.41 | F5: ZERODHA | G5: Consumer Non-durables
A6: INFY | B6: INFY.NS | C6: 44932 | D6: 12 | E6: 1443.43 | F6: ZERODHA | G6: Information Technology
A7: ITC | B7: ITC.NS | C7: 44593 | D7: 83 | E7: 324.41 | F7: ZERODHA | G7: Consumer Non-durables
A8: ITCHOTELS | B8: ITCHOTELS.NS | C8: 45670 | D8: 8 | E8: 436.45 | F8: ZERODHA | G8: Hotels
A9: KEI | B9: KEI.NS | C9: 45444 | D9: 7 | E9: 4429.8 | F9: ZERODHA | G9: Cables
A10: MARICO | B10: MARICO.NS | C10: 44593 | D10: 9 | E10: 525.48 | F10: ZERODHA | G10: Consumer Non-durables
A11: PERSISTENT | B11: PERSISTENT.NS | C11: 44932 | D11: 5 | E11: 2413.17 | F11: ZERODHA | G11: Information Technology
A12: PIDILITIND | B12: PIDILITIND.NS | C12: 44932 | D12: 7 | E12: 2741.3 | F12: ZERODHA | G12: Chemicals
A13: RELIANCE | B13: RELIANCE.NS | C13: 44623 | D13: 19 | E13: 1290.22 | F13: ZERODHA | G13: Oil & Gas
... A15: SUNDARMFIN | B15: SUNDARMFIN.NS | C15: 45099 | D15: 5 | E15: 2875.16 | F15: ZERODHA | G15: Auto Parts

Sheet SIP
A1: Sr. | B1: Name | C1: SIP_Name | D1: ISIN Code | E1: Unit | F1: TYPE | G1: Investment_type | H1: Start_date | I1: Years_Till | J1: Total_Investment | K1: Initial_Investment | L1: Link
A2: 1 | B2: ADITYA BIRLA SL SHORT TERM FUND(G) | C2: Aditya Birla SL Short Term Fund(G) | D2: INF209K01942 | E2: 0 | F2: Regular | G2: One Time | H2: 44344 | I2: =(TODAY()-H2)/365.25 -> 4.0246407 | J2: 0 | K2: =J2 -> 0 | L2: Aditya Birla Sun Life Short Term Fund - Regular Plan - Growth [37.0711] | Aditya Birla Sun Life Mutual Fund - Moneycontrol
A3: 2 | B3: ADITYA BIRLA SUN LIFE MNC FUND - GROWTH-REGULAR PLAN | C3: Birla Sun Life MNC Fund | D3: INF209K01322 | E3: 0 | F3: Regular | G3: SIP | H3: 44027 | I3: =(TODAY()-H3)/365.25 -> 4.8925394 | J3: 0 | K3: =J3 -> 0 | L3: https://www.moneycontrol.com/mutual-funds/amc-details/BS
A4: 3 | B4: ADITYA BIRLA SUN LIFE MUTUAL FUND TAX RELIEF 96 GROWTH | C4: Birla Sun Life Tax Relief 96 | D4: INF209K01108 | E4: 0 | F4: Tax Saver | G4: One Time | H4: 43101 | I4: =(TODAY()-H4)/365.25 -> 7.4277892 | J4: 0 | K4: =J4 -> 0 | L4: https://www.moneycontrol.com/mutual-funds/amc-details/BS
A5: 16 | B5: HDFC BALANCED DIRECT FUND | C5: HDFC Balanced Advantage Fund - Direct Plan - Growth | D5: INF179K01WA6 | E5: 82 | F5: Direct | G5: SIP | H5: 44935 | I5: =(TODAY()-H5)/365.25 -> 2.4065708 | J5: 33000 | K5: =J5 -> 33000
A6: 5 | B6: KOTAK LOW DURATION STD GROWTH | C6: Kotak Low Duration Fund | D6: INF178L01202 | E6: 0 | F6: Regular | G6: One Time | H6: 42948 | I6: =(TODAY()-H6)/365.25 -> 7.8466804 | J6: 0 | K6: =J6 -> 0 | L6: https://www.moneycontrol.com/mutual-funds/amc-details/KM
A7: 6 | B7: KOTAK MUTUAL TAX SAVER FUND | C7: Kotak Tax Saver | D7: INF174K01369 | E7: 0 | F7: Tax Saver | G7: One Time | H7: 43101 | I7: =(TODAY()-H7)/365.25 -> 7.4277892 | J7: 0 | K7: =J7 -> 0 | L7: https://www.moneycontrol.com/mutual-funds/amc-details/KM
A8: 7 | B8: KOTAK FLEXICAP FUND GR (REG PLAN) | C8: Kotak Flexicap Fund | D8: INF174K01336 | E8: 4806.783 | F8: Regular | G8: SIP | H8: 43235 | I8: =(TODAY()-H8)/365.25 -> 7.0609172 | J8: 170843.34 | K8: =J8 -> 170843.34 | L8: https://www.moneycontrol.com/mutual-funds/amc-details/KM
A9: 4 | B9: KOTAK FOCUSED EQUITY FUND GROWTH (REGULAR PLAN) | C9: Kotak Focused Equity Fund | D9: INF174KA1EK3 | E9: 10303.074 | F9: Regular | G9: SIP | H9: 44027 | I9: =(TODAY()-H9)/365.25 -> 4.8925394 | J9: 145000 | K9: =J9 -> 145000 | L9: https://www.moneycontrol.com/mf/mfinfo/amc_sch_listing.php?ffid=KM
A10: 9 | B10: NIPPON INDIA INCOME FUND - GROWTH | C10: Nippon India Income Fund | D10: INF204K01CL1 | E10: 0 | F10: Regular | G10: SIP | H10: 44027 | I10: =(TODAY()-H10)/365.25 -> 4.8925394 | J10: 0 | K10: =J10 -> 0 | L10: https://www.moneycontrol.com/mutual-funds/amc-details/RC
A11: 8 | B11: NIPPON INDIA GOLD SAVINGS FUND - SIP | C11: Nippon India Gold Savings Fund | D11: INF204K01KN0 | E11: 651.662 | F11: Regular | G11: SIP | H11: 44058 | I11: =(TODAY()-H11)/365.25 -> 4.807666 | J11: 13000 | K11: =J11 -> 13000 | L11: https://www.moneycontrol.com/mutual-funds/nav/nippon-india-gold-savings-fund-growth/MRC647
A12: 12 | B12: NIPPON INDIA PHARMA | C12: Nippon India Pharma Fund | D12: INF204K01968 | E12: 939 | F12: Regular | G12: SIP | H12: 43344 | I12: =(TODAY()-H12)/365.25 -> 6.7624914 | J12: 235000 | K12: =J12 -> 235000 | L12: https://www.moneycontrol.com/mutual-funds/amc-details/RC
A13: 13 | B13: NIPPON INDIA SMALL CAP | C13: Nippon India Small Cap | D13: INF204K01HY3 | E13: 1418 | F13: Regular | G13: SIP | H13: 44454 | I13: =(TODAY()-H13)/365.25 -> 3.7234771 | J13: 126000 | K13: =J13 -> 126000 | L13: https://www.moneycontrol.com/mutual-funds/nav/nippon-india-small-cap-fund-growth/MRC587
A14: 15 | B14: ADITYA BIRLA SUN LIFE FRONTLINE EQUITY FUND - REGULAR PLAN - GROWTH | C14: Birla Sun Life Frontline Eqt Fund | D14: INF209K01BR9 | E14: 0 | F14: Regular | G14: One Time | H14: 44621 | I14: =(TODAY()-H14)/365.25 -> 3.266256 | J14: 0 | K14: =J14 -> 0 | L14: https://www.moneycontrol.com/mutual-funds/nav/aditya-birla-sun-life-frontline-equity-fund/MAC031
A15: 14 | B15: NIPPON INDIA VALUE FUND | C15: Nippon India Value Fund | D15: INF204K01GB3 | E15: 521 | F15: Regular | G15: SIP | H15: 44454 | I15: =(TODAY()-H15)/365.25 -> 3.7234771 | J15: 67500 | K15: =J15 -> 67500 | L15: https://www.moneycontrol.com/mutual-funds/nav/nippon-india-value-fund/MRC098
A16: 17 | B16: PARAG PARIKH FLEXI DIRECT FUND | C16: Parag Parikh Flexi Cap Fund - Direct Plan - Growth | D16: INF879O01027 | E16: 916 | F16: Direct | G16: SIP | H16: 44935 | I16: =(TODAY()-H16)/365.25 -> 2.4065708 | J16: 64360 | K16: =J16 -> 64360
A17: 18 | B17: Tata Gold ETF Fund of Fund | C17: Tata Gold ETF Fund of Fund | D17: INF277KA1869 | E17: 499.975 | F17: Direct | G17: SIP | H17: 45310 | J17: 5000 | K17: =J17 -> 5000

Sheet SIP_Name
A1: ISIN | B1: SIP_NICK_NAME | C1: BRAND | D1: FUND_TYPE | E1: INVESTMENT_RANGE
A2: INF174K01336 | B2: KOTAK STD MULT | C2: KOTAK | D2: EQUITY | E2: LOW-MID
A3: INF174K01369 | B3: KOTAK TAX SAVER | C3: KOTAK | D3: ELSS | E3: MID-LONG
A4: INF174KA1EK3 | B4: KOTAK FOCUSED EQUITY SIP | C4: KOTAK | D4: EQUITY | E4: LOW-MID
A5: INF178L01202 | B5: KOTAK LOW DUR | C5: KOTAK | D5: DEBT | E5: LOW
A6: INF204K01968 | B6: NIPPON IND PHARMA | C6: NIPPON | D6: EQUITY | E6: LOW-MID
A7: INF204K01CL1 | B7: NIPPON IND INCOME SIP | C7: NIPPON | D7: DEBT | E7: MID-LONG
A8: INF204K01KN0 | B8: NIPPON IND GOLD SIP | C8: NIPPON | D8: COMMODITY | E8: LONG
A9: INF209K01108 | B9: ABSL TAX RELIEF | C9: ABSL | D9: ELSS | E9: MID-LONG
A10: INF209K01322 | B10: ABSL MNC FUND SIP | C10: ABSL | D10: EQUITY | E10: LOW-MID
A11: INF209K01942 | B11: ABSL SHORT TERM | C11: ABSL | D11: DEBT | E11: LOW
A12: INF204K01HY3 | B12: NIPPON INDIA SMALL CAP | C12: NIPPON | D12: EQUITY | E12: LOW-MID
... A17: INF277KA1869 | B17: Tata Gold ETF Fund of Fund | C17: TATA | D17: EQUITY | E17: MID-LONG

Sheet stocks and mf
A1: Stocks/ETFs | D1: Holdings - 24-Nov-23 IST
A2: Security | B2: No. of Smallcases | C2: Quantity | D2: Average Cost â‚¹ | E2: Portfolio Weight % | F2: LTP â‚¹ | G2: Invested Value â‚¹ | H2: Current Value â‚¹ | I2: P & L â‚¹ | J2: Net Change % | K2: Daily Change â‚¹ | L2: Daily Change %
A3: ASIANPAINT | B3: 1 | C3: 2 | D3: 2846.95 | E3: 3.24 | F3: 3128.5 | G3: 5693.9 | H3: 6257 | I3: 563.1 | J3: 9.89 | K3: 5.55 | L3: 0.18
A4: ASTRAL | B4: 1 | C4: 5 | D4: 1551.52 | E4: 5.01 | F4: 1938.1 | G4: 7757.6 | H4: 9690.5 | I4: 1932.9 | J4: 24.92 | K4: -15.85 | L4: -0.81
A5: CDSL | B5: 0 | C5: 25 | D5: 1289.22 | E5: 23.07 | F5: 1783.5 | G5: 32230.5 | H5: 44587.5 | I5: 12357 | J5: 38.34 | K5: -8.6 | L5: -0.48
A6: HINDUNILVR | B6: 1 | C6: 4 | D6: 2624.14 | E6: 5.2 | F6: 2511.5 | G6: 10496.56 | H6: 10046 | I6: -450.56 | J6: -4.29 | K6: -8.4 | L6: -0.33
A7: INFY | B7: 1 | C7: 7 | D7: 1422.35 | E7: 5.23 | F7: 1443.75 | G7: 9956.45 | H7: 10106.25 | I7: 149.8 | J7: 1.5 | K7: -5.5 | L7: -0.38
A8: ITC | B8: 1 | C8: 51 | D8: 256.49 | E8: 11.58 | F8: 438.75 | G8: 13080.99 | H8: 22376.25 | I8: 9295.26 | J8: 71.06 | K8: -1.6 | L8: -0.36
A9: JIOFIN | B9: 1 | C9: 3 | D9: 117.39 | E9: 0.34 | F9: 220.85 | G9: 352.17 | H9: 662.55 | I9: 310.38 | J9: 88.13 | K9: -0.4 | L9: -0.18
A10: LAOPALA | B10: 1 | C10: 18 | D10: 385.87 | E10: 3.57 | F10: 383.05 | G10: 6945.66 | H10: 6894.9 | I10: -50.76 | J10: -0.73 | K10: 1.55 | L10: 0.41
A11: MARICO | B11: 1 | C11: 25 | D11: 511.44 | E11: 6.91 | F11: 533.95 | G11: 12786 | H11: 13348.75 | I11: 562.75 | J11: 4.4 | K11: 3.05 | L11: 0.57
A12: PERSISTENT | B12: 1 | C12: 2 | D12: 4329.6 | E12: 6.62 | F12: 6396.35 | G12: 8659.2 | H12: 12792.7 | I12: 4133.5 | J12: 47.74 | K12: 17.5 | L12: 0.27
A13: PIDILITIND | B13: 1 | C13: 4 | D13: 2572 | E13: 5.17 | F13: 2496.05 | G13: 10288 | H13: 9984.2 | I13: -303.8 | J13: -2.95 | K13: -13.25 | L13: -0.53
A14: REDINGTON | B14: 1 | C14: 64 | D14: 172.16 | E14: 5.36 | F14: 161.8 | G14: 11018.24 | H14: 10355.2 | I14: -663.04 | J14: -6.02 | K14: 3.65 | L14: 2.31
... A17: SUNDARMFIN | B17: 1 | C17: 4 | D17: 2602.7 | E17: 6.46 | F17: 3124 | G17: 10410.8 | H17: 12496 | I17: 2085.2 | J17: 20.03 | K17: -11.9 | L17: -0.38
A19: Smallcases
A20: Dividend Aristocrats | B20: - | C20: - | D20: - | E20: 66.24 | F20: - | G20: 120532.25 | H20: 128041.65 | I20: 7509.4 | J20: 6.23 | K20: - | L20: -
A22: Fund Name | B22: AMC Name | C22: Category | D22: Sub-Category | E22: Plan Type | F22: Option Type | G22: NAV â‚¹ | H22: Units | I22: Invested Amt â‚¹ | J22: Current Value â‚¹ | K22: Weight % | L22: P&L â‚¹ | M22: P&L % | N22: XIRR % | O22: Invested Since
A23: Aditya Birla SL MNC Fund | B23: Aditya Birla Sun Life AMC Limited | C23: Equity | D23: Thematic Fund - MNC | E23: Standard | F23: Growth | G23: 1095.25 | H23: 5.89 | I23: 5518.27 | J23: 6455.4 | K23: 0.53 | L23: 937.13 | M23: 16.98 | N23: 1.95 | O23: 44026
A24: Aditya Birla SL Multi-Cap Fund | B24: Aditya Birla Sun Life AMC Limited | C24: Equity | D24: Multi Cap Fund | E24: Standard | F24: Growth | G24: 14.65 | H24: 393.95 | I24: 4770.73 | J24: 5771.37 | K24: 0.48 | L24: 1000.64 | M24: 20.97 | N24: 26.37 | O24: 44957
A25: HDFC Balanced Advantage Fund | B25: HDFC Asset Management Company Limited | C25: Hybrid | D25: Balanced Advantage Fund | E25: Direct | F25: Growth | G25: 423.38 | H25: 71.91 | I25: 27998.7 | J25: 30445.33 | K25: 2.51 | L25: 2446.63 | M25: 8.74 | N25: 28.83 | O25: 44935
A26: Kotak Flexicap Fund | B26: Kotak Mahindra Asset Management Company Limited | C26: Equity | D26: Flexi Cap Fund | E26: Standard | F26: Growth | G26: 61.76 | H26: 4806.78 | I26: 170840.48 | J26: 296886.15 | K26: 24.49 | L26: 126045.67 | M26: 73.78 | N26: 13.08 | O26: 42938
A27: Kotak Focused Equity Fund | B27: Kotak Mahindra Asset Management Company Limited | C27: Equity | D27: Focused Fund | E27: Standard | F27: Growth | G27: 18.81 | H27: 10303.07 | I27: 144992.76 | J27: 193780.23 | K27: 15.98 | L27: 48787.47 | M27: 33.65 | N27: 13.98 | O27: 44026
A28: Parag Parikh Flexi Cap Fund | B28: PPFAS Asset Management Pvt. Ltd. | C28: Equity | D28: Flexi Cap Fund | E28: Direct | F28: Growth | G28: 66.24 | H28: 809.96 | I28: 48497.59 | J28: 53650.22 | K28: 4.43 | L28: 5152.63 | M28: 10.62 | N28: 32.06 | O28: 44935
A29: Nippon India Gold Savings Fund | B29: Nippon Life India Asset Management Limited | C29: Commodity | D29: FoFs - Gold | E29: Standard | F29: Growth | G29: 24.16 | H29: 651.66 | I29: 12999.36 | J29: 15744.15 | K29: 1.3 | L29: 2744.79 | M29: 21.11 | N29: 7.14 | O29: 44060
A30: Nippon India Pharma Fund | B30: Nippon Life India Asset Management Limited | C30: Equity | D30: Sectoral Fund - Pharma & Health Care | E30: Standard | F30: Growth | G30: 370 | H30: 939.46 | I30: 234990.39 | J30: 347602.26 | K30: 28.67 | L30: 112611.88 | M30: 47.92 | N30: 18.03 | O30: 43346
A31: Nippon India Small Cap Fund | B31: Nippon Life India Asset Management Limited | C31: Equity | D31: Small Cap Fund | E31: Standard | F31: Growth | G31: 128.9 | H31: 1400.07 | I31: 123274.45 | J31: 180465.72 | K31: 14.89 | L31: 57191.27 | M31: 46.39 | N31: 28.77 | O31: 44441
A32: Nippon India Value Fund | B32: Nippon Life India Asset Management Limited | C32: Equity | D32: Value Fund | E32: Standard | F32: Growth | G32: 160.78 | H32: 507.28 | I32: 64996.69 | J32: 81561.26 | K32: 6.73 | L32: 16564.57 | M32: 25.49 | N32: 21.46 | O32: 44455
A33: Total | I33: 838879.43 | J33: 1212362.1 | K33: 100 | L33: 373482.66 | M33: 44.52

Sheet FD_RD
A1: Sr_No | B1: TYPE | C1: Account_No | D1: Nick_Name | E1: Deposit_Date | F1: ROI(%p.a) | G1: Incremental | H1: Tenor | I1: Maturity_Date | J1: Maturity_Amount | K1: RD_Installment | L1: Available_Balance | M1: BANK
A2: 0 | B2: PPF | C2: 33436074337 | D2: Mr. VINEET KUMAR SARASWAT | E2: 41586 | F2: 0.071 | G2: 0 | H2: 15 | I2: =E2+(H2*365.25) -> 47064.75 | J2: =L2 -> 428312 | L2: 428312 | M2: SBI
A3: 1 | B3: FD | C3: 43971647953 | D3: Mr. VINEET KUMAR SARASWAT | E3: 45751 | F3: 0.0725 | G3: 0 | H3: 1 | I3: =E3+444 -> 46195 | J3: 873085 | L3: 800000 | M3: SBI
A4: 2 | B4: FD | C4: 43971669217 | D4: Mr. VINEET KUMAR SARASWAT | E4: 45751 | F4: 0.0725 | G4: 0 | H4: 1 | I4: =E4+444 -> 46195 | J4: 1091356 | L4: 1000000 | M4: SBI
A5: 3 | B5: FD | C5: 43971646223 | D5: Mr. VINEET KUMAR SARASWAT | E5: 45751 | F5: 0.0725 | G5: 0 | H5: 1 | I5: =E5+444 -> 46195 | J5: 1309627 | L5: 1200000 | M5: SBI
A6: 7 | B6: NRE | C6: 39435504915 | D6: Mr. VINEET KUMAR SARASWAT | E6: 44307 | F6: 0.027 | G6: 0 | H6: 10 | I6: =E6+(H6*365.25) -> 47959.5 | J6: 0 | L6: =J6 -> 0 | M6: SBI
A7: 8 | B7: NRO | C7: 20181220065 | D7: Mr. VINEET KUMAR SARASWAT | E7: 44307 | F7: 0.027 | G7: 0 | H7: 10 | I7: =E7+(H7*365.25) -> 47959.5 | J7: 0 | L7: =J7 -> 0 | M7: SBI
A8: 9 | B8: SAVING | C8: 6.1260001e+15 | D8: Mr. VINEET KUMAR SARASWAT | E8: 44533 | F8: 0 | G8: 0 | H8: 10 | I8: =E8+(H8*365.25) -> 48185.5 | J8: 0 | L8: =J8 -> 0 | M8: PNB

Sheet LIC
A1: Policy_Number | B1: Date_Of_Commence | C1: Due_Dates | D1: Premium_Amount | E1: Payment_Date | F1: Premium_Paid | G1: Acc_Pre_Paid | H1: Service_ax | I1: Sum_Assured | J1: Bonus
A2: 234397289 | B2: 39627 | C2: 39627 | D2: 2347 | E2: 39627 | F2: 2347 | G2: =F2 -> 2347 | H2: 0 | I2: 200000 | J2: 2085.1064
A3: 234397289 | B3: 39627 | C3: 39719 | D3: 2347 | E3: 39719 | F3: 2347 | G3: =G2+F3 -> 4694 | H3: 0 | I3: 200000 | J3: 4170.2128
A4: 234397289 | B4: 39627 | C4: 39810 | D4: 2347 | E4: 39810 | F4: 2347 | G4: =G3+F4 -> 7041 | H4: 0 | I4: 200000 | J4: 6255.3191
A5: 234397289 | B5: 39627 | C5: 39900 | D5: 2347 | E5: 39900 | F5: 2347 | G5: =G4+F5 -> 9388 | H5: 0 | I5: 200000 | J5: 8340.4255
A6: 234397289 | B6: 39627 | C6: 39992 | D6: 2347 | E6: 39992 | F6: 2347 | G6: =G5+F6 -> 11735 | H6: 0 | I6: 200000 | J6: 10425.532
A7: 234397289 | B7: 39627 | C7: 40084 | D7: 2347 | E7: 40084 | F7: 2347 | G7: =G6+F7 -> 14082 | H7: 0 | I7: 200000 | J7: 12510.638
A8: 234397289 | B8: 39627 | C8: 40175 | D8: 2347 | E8: 40175 | F8: 2347 | G8: =G7+F8 -> 16429 | H8: 0 | I8: 200000 | J8: 14595.745
A9: 234397289 | B9: 39627 | C9: 40265 | D9: 2347 | E9: 40265 | F9: 2347 | G9: =G8+F9 -> 18776 | H9: 0 | I9: 200000 | J9: 16680.851
A10: 234397289 | B10: 39627 | C10: 40357 | D10: 2347 | E10: 40357 | F10: 2347 | G10: =G9+F10 -> 21123 | H10: 0 | I10: 200000 | J10: 18765.957
A11: 234397289 | B11: 39627 | C11: 40449 | D11: 2347 | E11: 40449 | F11: 2347 | G11: =G10+F11 -> 23470 | H11: 0 | I11: 200000 | J11: 20851.064
A12: 234397289 | B12: 39627 | C12: 40540 | D12: 2347 | E12: 40540 | F12: 2347 | G12: =G11+F12 -> 25817 | H12: 0 | I12: 200000 | J12: 22936.17
A13: 234397289 | B13: 39627 | C13: 40630 | D13: 2347 | E13: 40630 | F13: 2347 | G13: =G12+F13 -> 28164 | H13: 0 | I13: 200000 | J13: 25021.277
A14: 234397289 | B14: 39627 | C14: 40722 | D14: 2347 | E14: 40722 | F14: 2347 | G14: =G13+F14 -> 30511 | H14: 0 | I14: 200000 | J14: 27106.383
... A87: 117645635 | B87: 41834 | C87: 45487 | D87: 18966 | E87: 45464 | F87: 2347 | G87: =G86+F87 -> 550841 | H87: 0 | I87: 500000 | J87: 142800
A88: 234397289 | B88: 39627 | C88: 45563 | D88: 2347 | G88: =G87+F88 -> 550841 | H88: 0 | I88: 200000
A89: 234397289 | B89: 39627 | C89: 45654 | D89: 2347 | G89: =G88+F89 -> 550841 | H89: 0 | I89: 200000
A90: 117645635 | B90: 41834 | C90: 45671 | D90: 18966 | G90: =G89+F90 -> 550841 | I90: 500000
A91: 234397289 | B91: 39627 | C91: 45744 | D91: 2347 | G91: =G90+F91 -> 550841 | H91: 0 | I91: 200000
A92: 234397289 | B92: 39627 | C92: 45836 | D92: 2347 | G92: =G91+F92 -> 550841 | H92: 0 | I92: 200000
A93: 117645635 | B93: 41834 | C93: 45852 | D93: 18966 | G93: =G92+F93 -> 550841 | I93: 500000
A94: 234397289 | B94: 39627 | C94: 45928 | D94: 2347 | G94: =G93+F94 -> 550841 | H94: 0 | I94: 200000
A95: 234397289 | B95: 39627 | C95: 46019 | D95: 2347 | G95: =G94+F95 -> 550841 | H95: 0 | I95: 200000
A96: 117645635 | B96: 41834 | C96: 46036 | D96: 18966 | G96: =G95+F96 -> 550841 | I96: 500000
A97: 234397289 | B97: 39627 | C97: 46109 | D97: 2347 | G97: =G96+F97 -> 550841 | H97: 0 | I97: 200000
A98: 234397289 | B98: 39627 | C98: 46201 | D98: 2347 | G98: =G97+F98 -> 550841 | H98: 0 | I98: 200000
A99: 117645635 | B99: 41834 | C99: 46217 | D99: 18966 | G99: =G98+F99 -> 550841 | I99: 500000
A100: 234397289 | B100: 39627 | C100: 46293 | D100: 2347 | G100: =G99+F100 -> 550841 | H100: 0 | I100: 200000
A101: 234397289 | B101: 39627 | C101: 46384 | D101: 2347 | G101: =G100+F101 -> 550841 | H101: 0 | I101: 200000
A102: 117645635 | B102: 41834 | C102: 46401 | D102: 18966 | G102: =G101+F102 -> 550841 | I102: 500000
A103: 234397289 | B103: 39627 | C103: 46474 | D103: 2347 | G103: =G102+F103 -> 550841 | H103: 0 | I103: 200000
A104: 234397289 | B104: 39627 | C104: 46566 | D104: 2347 | G104: =G103+F104 -> 550841 | H104: 0 | I104: 200000
A105: 117645635 | B105: 41834 | C105: 46582 | D105: 18966 | G105: =G104+F105 -> 550841 | I105: 500000
A106: 234397289 | B106: 39627 | C106: 46658 | D106: 2347 | G106: =G105+F106 -> 550841 | H106: 0 | I106: 200000
A107: 234397289 | B107: 39627 | C107: 46749 | D107: 2347 | G107: =G106+F107 -> 550841 | H107: 0 | I107: 200000
A108: 117645635 | B108: 41834 | C108: 46766 | D108: 18966 | G108: =G107+F108 -> 550841 | I108: 500000
A109: 234397289 | B109: 39627 | C109: 46839 | D109: 2347 | G109: =G108+F109 -> 550841 | H109: 0 | I109: 200000
A110: 234397289 | B110: 39627 | C110: 46932 | D110: 2347 | G110: =G109+F110 -> 550841 | H110: 0 | I110: 200000
A111: 117645635 | B111: 41834 | C111: 46948 | D111: 18966 | G111: =G110+F111 -> 550841 | I111: 500000
A112: 234397289 | B112: 39627 | C112: 47024 | D112: 2347 | G112: =G111+F112 -> 550841 | H112: 0 | I112: 200000
...

Sheet GOLD_RESERVE
A1: SR | B1: PUR_DATE | C1: Commodity | D1: INVOICE_NUM | E1: ITEM_CODE | F1: ITEM | G1: QUANTITY | H1: QUALITY | I1: GOLD_WEIGHT_GRMS | J1: GOLD_RATE_PER_1GRAM | K1: GOLD_RATE_INR_PER_GRAM | L1: NET_WEIGHT | M1: MAKING_CHARGE | N1: %_MAKING | O1: AMOUNT | P1: %_TAX | Q1: TAX_AMOUNT | R1: TTL_AMOUNT_QAR | S1: TTL_AMOUNT_INR | T1: JEWELLERS | U1: PLACE | V1: P_TYPE | W1: REMARK
A2: 1 | B2: 42005 | C2: Gold | D2: A001 | E2: C004 | F2: CHAIN | G2: 1 | T2: KANPUR | U2: KANPUR | V2: SELF | W2: VINEET
A3: 2 | B3: 42005 | C3: Gold | D3: A002 | E3: C005 | F3: LOCKET | G3: 1 | T3: KANPUR | U3: KANPUR | V3: SELF | W3: VINEET
A4: 3 | B4: 43070 | C4: Gold | D4: A003 | E4: C002 | F4: RING | G4: 1 | T4: HATHRAS | U4: HATHRAS | V4: SELF | W4: VINEET
A5: 4 | B5: 43070 | C5: Gold | D5: A004 | E5: C003 | F5: RING | G5: 1 | T5: KANPUR | U5: KANPUR | V5: SELF | W5: VINEET
A6: 5 | B6: 43070 | C6: Gold | D6: A005 | E6: C006 | F6: BANGLE | G6: 4 | T6: MUNNILAL | U6: KANPUR | V6: SELF | W6: ARTI
A7: 6 | B7: 43070 | C7: Gold | D7: A006 | E7: C007 | F7: NECKLACE | G7: 1 | T7: MUNNILAL | U7: KANPUR | V7: SELF | W7: ARTI
A8: 7 | B8: 43070 | C8: Gold | D8: A007 | E8: C008 | F8: KANTHI | G8: 1 | T8: MUNNILAL | U8: KANPUR | V8: SELF | W8: ARTI
A9: 8 | B9: 43070 | C9: Gold | D9: A008 | E9: C009 | F9: EARRING | G9: 1 | T9: KSHAMTA MAAM | U9: DELHI | V9: SELF | W9: ARTI
A10: 9 | B10: 43070 | C10: Gold | D10: A009 | E10: C010 | F10: EARRING | G10: 1 | T10: MUNNILAL | U10: KANPUR | V10: SELF | W10: ARTI
A11: 10 | B11: 43760 | C11: Gold | D11: A010 | E11: C001 | F11: RING | G11: 1 | H11: 22K | I11: 3.35 | J11: 169 | K11: =J11*19.41 -> 3280.29 | L11: =I11 -> 3.35 | M11: 73.5 | N11: =M11/(I11*J11) -> 0.12982425 | O11: =(I11*J11)+M11 -> 639.65 | P11: 0 | Q11: =O11*P11 -> 0 | R11: =O11+Q11 -> 639.65 | S11: =R11*K11/J11 -> 12415.606 | T11: MALABAR | U11: DOHA | V11: GIFT | W11: KAPIL BHAI
A12: 11 | B12: 44148 | C12: Gold | D12: A011 | E12: C011 | F12: Nose Ring | G12: 1 | H12: 20K | I12: 1.99 | T12: MUNNILAL | U12: KANPUR | V12: SELF | W12: ARTI
A13: 12 | B13: 43784 | C13: Gold | D13: WETGNC004603 | E13: 800110269085 | F13: NECKLACE | G13: 1 | H13: 22K | I13: 13.72 | J13: 169.5 | K13: =J13*19.72 -> 3342.54 | L13: =I13 -> 13.72 | M13: 316.41 | N13: =M13/(I13*J13) -> 0.13605872 | O13: =(I13*J13)+M13 -> 2641.95 | P13: 0 | Q13: =O13*P13 -> 0 | R13: =O13+Q13 -> 2641.95 | S13: =R13*K13/J13 -> 52099.254 | T13: KALYAN | U13: DOHA | V13: SELF | W13: ARTI
A14: 13 | B14: 43847 | C14: Gold | D14: QMDLC10500020727 | E14: 131000449407 | F14: EARRING | G14: 1 | H14: 22K | I14: 1.29 | J14: 179 | K14: =J14*19.51 -> 3492.29 | L14: 1.29 | M14: 44.09 | N14: =M14/(I14*J14) -> 0.19094019 | O14: =(I14*J14)+M14 -> 275 | P14: 0 | Q14: =O14*P14 -> 0 | R14: =O14+Q14 -> 275 | S14: =R14*K14/J14 -> 5365.25 | T14: MALABAR | U14: DOHA | V14: SELF | W14: ARTI
A15: 14 | B15: 43867 | C15: Gold | D15: WETGNC005891 | E15: 800110303818 | F15: RING | G15: 1 | H15: 22K | I15: 4.43 | J15: 179.5 | K15: =J15*19.55 -> 3509.225 | L15: =I15 -> 4.43 | M15: 95.81 | N15: =M15/(I15*J15) -> 0.12048769 | O15: =(I15*J15)+M15 -> 890.995 | P15: 0 | Q15: =O15*P15 -> 0 | R15: =O15+Q15 -> 890.995 | S15: =R15*K15/J15 -> 17418.952 | T15: KALYAN | U15: DOHA | V15: GIFT | W15: DOLLY
A16: 15 | B16: 43869 | C16: Gold | D16: HBKGNB002614 | E16: 800110270040 | F16: CHAIN | G16: 1 | H16: 22K | I16: 4.64 | J16: 181 | K16: =J16*19.65 -> 3556.65 | L16: 4.63 | M16: 117.16 | N16: =M16/(I16*J16) -> 0.13950276 | O16: =(I16*J16)+M16 -> 957 | P16: 0 | Q16: =O16*P16 -> 0 | R16: =O16+Q16 -> 957 | S16: =R16*K16/J16 -> 18805.05 | T16: KALYAN | U16: DOHA | V16: GIFT | W16: KIRTI
A17: 16 | B17: 43869 | C17: Gold | D17: HBKGNB002614 | E17: 800110221945 | F17: PENDANT | G17: 1 | H17: 22K | I17: 1.74 | J17: 181 | K17: =J17*19.65 -> 3556.65 | L17: 1.71 | M17: 50.87 | N17: =M17/(I17*J17) -> 0.16152283 | O17: =(I17*J17)+M17 -> 365.81 | P17: 0 | Q17: =O17*P17 -> 0 | R17: =O17+Q17 -> 365.81 | S17: =R17*K17/J17 -> 7188.1665 | T17: KALYAN | U17: DOHA | V17: GIFT | W17: KIRTI
A18: 17 | B18: 44053 | C18: Gold | D18: QMDLC10300024044 | E18: 131000517089 | F18: COIN | G18: 1 | H18: 22K | I18: 4 | J18: 234.5 | K18: =J18*20.25 -> 4748.625 | L18: 4 | M18: 6 | N18: =M18/(I18*J18) -> 0.0063965885 | O18: =(I18*J18)+M18 -> 944 | P18: 0 | Q18: =O18*P18 -> 0 | R18: =O18+Q18 -> 944 | S18: =R18*K18/J18 -> 19116 | T18: MALABAR | U18: DOHA | V18: SELF | W18: ARTI
A19: 18 | B19: 44053 | C19: Gold | D19: QMDLC10300024044 | E19: 131000517135 | F19: COIN | G19: 2 | H19: 22K | I19: 4 | J19: 234.5 | K19: =J19*20.25 -> 4748.625 | L19: 4 | M19: 6 | N19: =M19/(I19*J19) -> 0.0063965885 | O19: =(I19*J19)+M19 -> 944 | P19: 0 | Q19: =O19*P19 -> 0 | R19: =O19+Q19 -> 944 | S19: =R19*K19/J19 -> 19116 | T19: MALABAR | U19: DOHA | V19: SELF | W19: ARTI
A20: 19 | B20: 44232 | C20: Gold | D20: HBKGPB001225 | E20: 800110342105 | F20: CHAIN | G20: 1 | H20: 22K | I20: 8.68 | J20: 208 | K20: =J20*20.05 -> 4170.4 | L20: 8.68 | M20: 135.56 | N20: =M20/(I20*J20) -> 0.07508419 | O20: =(I20*J20)+M20 -> 1941 | P20: 0 | Q20: =O20*P20 -> 0 | R20: =O20+Q20 -> 1941 | S20: =R20*K20/J20 -> 38917.05 | T20: KALYAN | U20: DOHA | V20: SELF | W20: HARSHI
A21: 20 | B21: 44510 | C21: SILVER | D21: PAPA65000 | E21: S001 | F21: BLOCK | G21: 1 | H21: 24K | I21: 1000 | J21: =K21/20 -> 3.25 | K21: 65 | L21: 1000 | M21: 0 | N21: =M21/(I21*J21) -> 0 | O21: =(I21*J21)+M21 -> 3250 | P21: 0 | Q21: =O21*P21 -> 0 | R21: =O21+Q21 -> 3250 | S21: =R21*K21/J21 -> 65000 | T21: PAPA_KNP | U21: DOHA | V21: SELF | W21: VIRAAJ
A22: 21 | B22: 44685 | C22: Gold | D22: HQ CS-041392 | E22: BAN002886 | F22: BANGLE | G22: 2 | H22: 22K | I22: 35.08 | J22: 205.7 | K22: =J22*20.95 -> 4309.415 | L22: 35.08 | M22: 1900 | N22: =M22/(I22*J22) -> 0.26330537 | O22: =(I22*J22)+M22 -> 9115.956 | P22: 0 | Q22: 32.005434 | R22: =O22+Q22 -> 9147.9614 | S22: =R22*K22/J22 -> 191649.79 | T22: GRK GOLD | U22: SIN | V22: SELF | W22: ARTI
A23: 22 | B23: 44685 | C23: Gold | D23: HQ CS-041392 | E23: RIN012799 | F23: RING | G23: 1 | H23: 22K | I23: 0 | J23: 0 | K23: =J23*20.95 -> 0 | L23: 0 | M23: 0 | N23: 0 | O23: =(I23*J23)+M23 -> 0 | P23: 0 | Q23: 0 | R23: =O23+Q23 -> 0 | S23: 0 | T23: SOLD | U23: SIN | V23: SELF | W23: VINEET
A24: 23 | B24: 44685 | C24: SILVER | D24: HQ CS-041392 | E24: SIL001894 | F24: COW | G24: 1 | H24: 20k | I24: 17.88 | J24: 7.92 | K24: =J24*20.95 -> 165.924 | L24: 17.88 | M24: 35 | N24: =M24/(I24*J24) -> 0.24715838 | O24: =(I24*J24)+M24 -> 176.6096 | P24: 0 | Q24: =O24*P24 -> 0 | R24: =O24+Q24 -> 176.6096 | S24: =R24*K24/J24 -> 3699.9711 | T24: GRK GOLD | U24: SIN | V24: SELF | W24: ARTI
A25: 24 | B25: 44823 | C25: Gold | D25: WETGRC002981 | E25: 800110460272 | F25: EARRING | G25: 1 | H25: 22K | I25: 2.2 | J25: 195.5 | K25: =J25*21.9 -> 4281.45 | L25: 2.2 | M25: 84.9 | N25: =M25/(I25*J25) -> 0.19739595 | O25: =(I25*J25)+M25 -> 515 | P25: 0 | Q25: =O25*P25 -> 0 | R25: =O25+Q25 -> 515 | S25: =R25*K25/J25 -> 11278.5 | T25: KALYAN | U25: DOHA | V25: SELF | W25: ARTI
A26: 25 | B26: 44837 | C26: Gold | D26: QMDLC10200056539 | E26: 131001029667 | F26: EARRING | G26: 1 | H26: 22K | I26: 9.86 | J26: 200 | K26: =J26*22.5 -> 4500 | L26: 9.8 | M26: 508 | N26: =M26/(I26*J26) -> 0.25760649 | O26: =(I26*J26)+M26 -> 2480 | P26: 0 | Q26: =O26*P26 -> 0 | R26: =O26+Q26 -> 2480 | S26: =R26*K26/J26 -> 55800 | T26: MALABAR | U26: DOHA | V26: SELF | W26: ARTI
A27: 26 | B27: 44878 | C27: Gold | D27: WETGRB003312 | E27: 800110463172 | F27: CHAIN | G27: 1 | H27: 22K | I27: 20.54 | J27: 199.01 | K27: =J27*22.12 -> 4402.1012 | L27: =I27 -> 20.54 | M27: 422.33 | N27: =M27/(I27*J27) -> 0.10331814 | O27: =(I27*J27)+M27 -> 4509.9954 | P27: 0 | Q27: =O27*P27 -> 0 | R27: =O27+Q27 -> 4509.9954 | S27: =R27*K27/J27 -> 99761.098 | T27: KALYAN | U27: DOHA | V27: SELF | W27: VINEET
A28: 27 | B28: 45489 | C28: Gold | D28: BRVGTC001587 | E28: 800110574408 | F28: PENDANT | G28: 1 | H28: 22K | I28: 2.23 | J28: 280 | K28: =J28*22.92 -> 6417.6 | L28: 2.23 | M28: 111.6 | N28: =M28/(I28*J28) -> 0.17873158 | O28: =(I28*J28)+M28 -> 736 | P28: 0 | Q28: =O28*P28 -> 0 | R28: =O28+Q28 -> 736 | S28: =R28*K28/J28 -> 16869.12 | T28: KALYAN | U28: DOHA | V28: SELF | W28: HARSHI
A29: 28 | B29: 45513 | C29: Gold | D29: ALIGTSD00028 | E29: *** | F29: CHAIN | G29: 1 | H29: 22K | I29: 11.86 | J29: 279 | K29: 6425 | L29: 11.86 | M29: 487.0204 | N29: =M29/(I29*J29) -> 0.14718321 | O29: =(I29*J29)+M29 -> 3795.9604 | P29: 0 | Q29: 113.5 | R29: =O29+Q29 -> 3909.4604 | S29: =R29*K29/J29 -> 90029.688 | T29: KALYAN | U29: ALIGARH | V29: SELF | W29: VIRAAJ
A30: 29 | B30: 45569 | C30: Gold | D30: WETGTB001710 | E30: 800110581838 | F30: RING | G30: 1 | H30: 22K | I30: 8.26 | J30: 302.5 | K30: =J30*23.05 -> 6972.625 | L30: 8.26 | M30: 293.72 | N30: =M30/(I30*J30) -> 0.11755148 | O30: =(I30*J30)+M30 -> 2792.37 | P30: 0 | Q30: 0 | R30: =O30+Q30 -> 2792.37 | S30: =R30*K30/J30 -> 64364.128 | T30: GRK GOLD | U30: DOHA | V30: SELF | W30: VINEET
A31: 30 | B31: 45569 | C31: Gold | D31: WETGTB001710 | E31: 800710004990 | F31: PENDANT | G31: 1 | H31: 22K | I31: 14.38 | J31: 302.5 | K31: =J31*23.05 -> 6972.625 | L31: 14.38 | M31: 696.32 | N31: =M31/(I31*J31) -> 0.1600754 | O31: =(I31*J31)+M31 -> 5046.27 | P31: 0 | Q31: 0 | R31: =O31+Q31 -> 5046.27 | S31: =R31*K31/J31 -> 116316.52 | T31: GRK GOLD | U31: DOHA | V31: SELF | W31: VINEET
A32: 31 | B32: 45583 | C32: Gold | D32: BRVGTB001156 | E32: 800110545356 | F32: NECKLACE | G32: 1 | H32: 22K | I32: 45.25 | J32: 307 | K32: =J32*23.92 -> 7343.44 | L32: 45.25 | M32: 2640 | N32: =M32/(I32*J32) -> 0.19004085 | O32: =(I32*J32)+M32 -> 16531.75 | P32: 0 | Q32: =O32*P32 -> 0 | R32: =O32+Q32 -> 16531.75 | S32: =R32*K32/J32 -> 395439.46 | T32: KALYAN | U32: DOHA | V32: SELF | W32: ARTI

Sheet Asset
A1: Sr. | B1: Asset_Details | C1: Datadate | D1: Perchase_Date | E1: Perchase_Value | F1: Insurance_Date | G1: Ins_Valid_from | H1: Ins_Valid_To | I1: Insurance_Amount | J1: Insurance_Renewal_Date | K1: Obj_IDV | L1: Expected_Amount
A2: 1 | B2: Hyundai Car - DL9CAQ6746 | C2: =D2 -> 43383 | D2: 43383 | E2: 751000 | F2: 43383 | G2: =D2 -> 43383 | H2: 43747.25 | I2: 36013 | J2: =H2-7 -> 43740.25 | K2: 667276 | L2: =E2*90% -> 675900
A3: 2 | B3: Hyundai Car - DL9CAQ6746 | C3: =J2 -> 43740.25 | D3: 43383 | E3: =E2 -> 751000 | F3: 43747.25 | G3: =G2+365 -> 43748 | H3: =G3+365 -> 44113 | I3: 13291 | J3: =H3-7 -> 44106 | K3: 596778 | L3: =L2*90% -> 608310
A4: 2 | B4: Mitshubishi Car | C4: 44753 | D4: 44753 | E4: =70000*21.6 -> 1512000 | F4: 44613 | G4: =F4 -> 44613 | H4: =G4+365 -> 44978 | I4: =1800*21.6 -> 38880 | J4: =H4-7 -> 44971 | K4: =75000*21.6 -> 1620000 | L4: =E4 -> 1512000

Sheet SIP_Transations
A1: Scheme_Name | B1: ISIN Code | C1: Asset_Sub_Category | D1: SIP_Trnx_Type | E1: Folio_No. | F1: SIP_Trnx_Date | G1: Num_Units | H1: SIP_Buy_Price | I1: SIP_Invst_Amount
A2: KOTAK FLEXICAP FUND(G) | B2: INF174K01336 | C2: Flexi Cap Fund | D2: SIP | E2: 4343476/67 | F2: 43110 | G2: 9.16 | H2: 33.892 | I2: 310
A3: KOTAK FLEXICAP FUND(G) | B3: INF174K01336 | C3: Flexi Cap Fund | D3: STP | E3: 4343476/67 | F3: 43153 | G3: 31.06 | H3: 32.196 | I3: 1000
A4: KOTAK FLEXICAP FUND(G) | B4: INF174K01336 | C4: Flexi Cap Fund | D4: STP | E4: 4343476/67 | F4: 43154 | G4: 30.707 | H4: 32.566 | I4: 1000
A5: KOTAK FLEXICAP FUND(G) | B5: INF174K01336 | C5: Flexi Cap Fund | D5: STP | E5: 4343476/67 | F5: 43157 | G5: 30.346 | H5: 32.953 | I5: 1000
A6: KOTAK FLEXICAP FUND(G) | B6: INF174K01336 | C6: Flexi Cap Fund | D6: STP | E6: 4343476/67 | F6: 43158 | G6: 30.418 | H6: 32.875 | I6: 1000
A7: KOTAK FLEXICAP FUND(G) | B7: INF174K01336 | C7: Flexi Cap Fund | D7: STP | E7: 4343476/67 | F7: 43159 | G7: 30.553 | H7: 32.73 | I7: 1000
A8: KOTAK FLEXICAP FUND(G) | B8: INF174K01336 | C8: Flexi Cap Fund | D8: STP | E8: 4343476/67 | F8: 43160 | G8: 30.713 | H8: 32.559 | I8: 1000
A9: KOTAK FLEXICAP FUND(G) | B9: INF174K01336 | C9: Flexi Cap Fund | D9: STP | E9: 4343476/67 | F9: 43164 | G9: 61.94 | H9: 32.289 | I9: 2000
A10: KOTAK FLEXICAP FUND(G) | B10: INF174K01336 | C10: Flexi Cap Fund | D10: STP | E10: 4343476/67 | F10: 43165 | G10: 31.248 | H10: 32.002 | I10: 1000
A11: KOTAK FLEXICAP FUND(G) | B11: INF174K01336 | C11: Flexi Cap Fund | D11: STP | E11: 4343476/67 | F11: 43166 | G11: 31.595 | H11: 31.651 | I11: 1000
A12: KOTAK FLEXICAP FUND(G) | B12: INF174K01336 | C12: Flexi Cap Fund | D12: STP | E12: 4343476/67 | F12: 43167 | G12: 31.322 | H12: 31.926 | I12: 1000
A13: KOTAK FLEXICAP FUND(G) | B13: INF174K01336 | C13: Flexi Cap Fund | D13: STP | E13: 4343476/67 | F13: 43168 | G13: 31.381 | H13: 31.866 | I13: 1000
... A97: KOTAK FLEXICAP FUND(G) | B97: INF174K01336 | C97: Flexi Cap Fund | D97: STP | E97: 4343476/67 | F97: 43293 | G97: 29.692 | H97: 33.679 | I97: 1000
A98: ADITYA BIRLA SL TAX RELIEF '96(G) | B98: INF209K01108 | C98: Equity - ELSS | D98: SIP | E98: 1019420000 | F98: 43322 | G98: 77.28 | H98: 32.35 | I98: 2500
A99: NIPPON INDIA PHARMA FUND(G) | B99: INF204K01968 | C99: Equity - Sectoral Fund - Pharma & Health Care | D99: PUR | E99: 499203639934 | F99: 43346 | G99: 123.135 | H99: 162.423 | I99: 20000
A100: KOTAK LOW DURATION FUND(G) | B100: INF178L01202 | C100: Debt - Low Duration Fund | D100: Additional Purchase | E100: 4343476/67 | F100: 43347 | G100: 6.872 | H100: 2182.682 | I100: 14999
A101: ADITYA BIRLA SL TAX RELIEF '96(G) | B101: INF209K01108 | C101: Equity - ELSS | D101: STP | E101: 1019420000 | F101: 43364 | G101: 75.543 | H101: 31.77 | I101: 2400
A102: ADITYA BIRLA SL TAX RELIEF '96(G) | B102: INF209K01108 | C102: Equity - ELSS | D102: STP | E102: 1019420000 | F102: 43395 | G102: 83.045 | H102: 28.9 | I102: 2400
A103: ADITYA BIRLA SL TAX RELIEF '96(G) | B103: INF209K01108 | C103: Equity - ELSS | D103: STP | E103: 1019420000 | F103: 43426 | G103: 80.618 | H103: 29.77 | I103: 2400
A104: ADITYA BIRLA SL TAX RELIEF '96(G) | B104: INF209K01108 | C104: Equity - ELSS | D104: STP | E104: 1019420000 | F104: 43455 | G104: 78.585 | H104: 30.54 | I104: 2400
A105: ADITYA BIRLA SL TAX RELIEF '96(G) | B105: INF209K01108 | C105: Equity - ELSS | D105: STP | E105: 1019420000 | F105: 43486 | G105: 78.483 | H105: 30.58 | I105: 2400
A106: ADITYA BIRLA SL TAX RELIEF '96(G) | B106: INF209K01108 | C106: Equity - ELSS | D106: STP | E106: 1019420000 | F106: 43517 | G106: 80.999 | H106: 29.63 | I106: 2400
A107: ADITYA BIRLA SL TAX RELIEF '96(G) | B107: INF209K01108 | C107: Equity - ELSS | D107: STP | E107: 1019420000 | F107: 43546 | G107: 29.152 | H107: 31.11 | I107: 907
A108: KOTAK FLEXICAP FUND(G) | B108: INF174K01336 | C108: Flexi Cap Fund | D108: Additional Purchase | E108: 4343476/67 | F108: 43955 | G108: 863.916 | H108: 28.938 | I108: 25000
A109: KOTAK LOW DURATION FUND(G) | B109: INF178L01202 | C109: Debt - Low Duration Fund | D109: Additional Purchase | E109: 4343476/67 | F109: 43955 | G109: 2.03 | H109: 2462.528 | I109: 4999
A110: NIPPON INDIA PHARMA FUND(G) | B110: INF204K01968 | C110: Equity - Sectoral Fund - Pharma & Health Care | D110: PUR | E110: 499203639934 | F110: 43955 | G110: 110.381 | H110: 181.191 | I110: 20000
A111: ADITYA BIRLA SL MNC FUND-REG(G) | B111: INF209K01322 | C111: Equity - Thematic Fund - MNC | D111: Additional Purchase | E111: 1019420000 | F111: 44027 | G111: 6.903 | H111: 724.25 | I111: 5000
A112: KOTAK FOCUSED EQUITY FUND-REG(G) | B112: INF174KA1EK3 | C112: Equity - Focused Fund | D112: Additional Purchase | E112: 4343476/67 | F112: 44027 | G112: 515.226 | H112: 9.704 | I112: 5000
A113: NIPPON INDIA INCOME FUND(G) | B113: INF204K01CL1 | C113: Debt - Medium to Long Duration Fund | D113: PUR | E113: 499203639934 | F113: 44027 | G113: 71.344 | H113: 70.079 | I113: 5000
A114: NIPPON INDIA PHARMA FUND(G) | B114: INF204K01968 | C114: Equity - Sectoral Fund - Pharma & Health Care | D114: PUR | E114: 499203639934 | F114: 44027 | G114: 25.83 | H114: 193.566 | I114: 5000
A115: ADITYA BIRLA SL MNC FUND-REG(G) | B115: INF209K01322 | C115: Equity - Thematic Fund - MNC | D115: SIP | E115: 1019420000 | F115: 44060 | G115: 6.612 | H115: 756.18 | I115: 5000
A116: KOTAK FOCUSED EQUITY FUND-REG(G) | B116: INF174KA1EK3 | C116: Equity - Focused Fund | D116: SIP | E116: 4343476/67 | F116: 44060 | G116: 491.376 | H116: 10.175 | I116: 5000
A117: NIPPON INDIA GOLD SAVINGS FUND(G) | B117: INF204K01KN0 | C117: FoFs (Domestic / Overseas ) - Gold | D117: Systematic Investment | E117: 499203639934 | F117: 44060 | G117: 46.089 | H117: 21.696 | I117: 1000
A118: NIPPON INDIA INCOME FUND(G) | B118: INF204K01CL1 | C118: Debt - Medium to Long Duration Fund | D118: Systematic Investment | E118: 499203639934 | F118: 44060 | G118: 57.446 | H118: 69.627 | I118: 4000
A119: NIPPON INDIA PHARMA FUND(G) | B119: INF204K01968 | C119: Equity - Sectoral Fund - Pharma & Health Care | D119: Systematic Investment | E119: 499203639934 | F119: 44060 | G119: 22.407 | H119: 223.138 | I119: 5000
A120: ADITYA BIRLA SL MNC FUND-REG(G) | B120: INF209K01322 | C120: Equity - Thematic Fund - MNC | D120: SIP | E120: 1019420000 | F120: 44089 | G120: 6.252 | H120: 799.73 | I120: 5000
A121: KOTAK FOCUSED EQUITY FUND-REG(G) | B121: INF174KA1EK3 | C121: Equity - Focused Fund | D121: SIP | E121: 4343476/67 | F121: 44089 | G121: 478.353 | H121: 10.452 | I121: 5000
A122: NIPPON INDIA GOLD SAVINGS FUND(G) | B122: INF204K01KN0 | C122: FoFs (Domestic / Overseas ) - Gold | D122: Systematic Investment | E122: 499203639934 | F122: 44089 | G122: 46.697 | H122: 21.414 | I122: 1000
A123: NIPPON INDIA INCOME FUND(G) | B123: INF204K01CL1 | C123: Debt - Medium to Long Duration Fund | D123: Systematic Investment | E123: 499203639934 | F123: 44089 | G123: 57.563 | H123: 69.486 | I123: 4000
...

Sheet GOLD RATE
A1: GRAM | B1: GOLD_RATE | C1: High | D1: Low | E1: Change | F1: G_DATADATE
A2: 1 GRAM GOLD 24K | B2: 174.66 | C2: =B2*100.1% -> 174.83466 | D2: =B2*99.9% -> 174.48534 | E2: =C2-D2 -> 0.34932 | F2: 43775
A3: 1 GRAM GOLD 24K | B3: 172.39 | C3: =B3*100.1% -> 172.56239 | D3: =B3*99.9% -> 172.21761 | E3: =C3-D3 -> 0.34478 | F3: 43776
A4: 1 GRAM GOLD 24K | B4: 170.94 | C4: =B4*100.1% -> 171.11094 | D4: =B4*99.9% -> 170.76906 | E4: =C4-D4 -> 0.34188 | F4: 43777
A5: 1 GRAM GOLD 24K | B5: 170.93 | C5: =B5*100.1% -> 171.10093 | D5: =B5*99.9% -> 170.75907 | E5: =C5-D5 -> 0.34186 | F5: 43779
A6: 1 GRAM GOLD 24K | B6: 170.35 | C6: =B6*100.1% -> 170.52035 | D6: =B6*99.9% -> 170.17965 | E6: =C6-D6 -> 0.3407 | F6: 43780
A7: 1 GRAM GOLD 24K | B7: 170.57 | C7: =B7*100.1% -> 170.74057 | D7: =B7*99.9% -> 170.39943 | E7: =C7-D7 -> 0.34114 | F7: 43781
A8: 1 GRAM GOLD 24K | B8: 171.33 | C8: =B8*100.1% -> 171.50133 | D8: =B8*99.9% -> 171.15867 | E8: =C8-D8 -> 0.34266 | F8: 43782
A9: 1 GRAM GOLD 24K | B9: 171.69 | C9: =B9*100.1% -> 171.86169 | D9: =B9*99.9% -> 171.51831 | E9: =C9-D9 -> 0.34338 | F9: 43783
A10: 1 GRAM GOLD 24K | B10: 171.52 | C10: =B10*100.1% -> 171.69152 | D10: =B10*99.9% -> 171.34848 | E10: =C10-D10 -> 0.34304 | F10: 43784
A11: 1 GRAM GOLD 24K | B11: 171.53 | C11: =B11*100.1% -> 171.70153 | D11: =B11*99.9% -> 171.35847 | E11: =C11-D11 -> 0.34306 | F11: 43786
A12: 1 GRAM GOLD 24K | B12: 172.04 | C12: =B12*100.1% -> 172.21204 | D12: =B12*99.9% -> 171.86796 | E12: =C12-D12 -> 0.34408 | F12: 43787
A13: 1 GRAM GOLD 24K | B13: 172.37 | C13: =B13*100.1% -> 172.54237 | D13: =B13*99.9% -> 172.19763 | E13: =C13-D13 -> 0.34474 | F13: 43788
... A78: GRAM 22K | B78: 165.13 | C78: =B78*100.1% -> 165.29513 | D78: =B78*99.9% -> 164.96487 | E78: =C78-D78 -> 0.33026 | F78: 43833

Sheet CURRENCY
A1: CURRENCY | B1: AGAINST_DOLLAR | C1: DOLLAR_AGAINST_CURRENCY | D1: C_DATADATE
A2: Indian Rupee | B2: 71.78379 | C2: 0.013930722 | D2: 43833
A3: Indian Rupee | B3: 71.3452 | C3: 0.01401636 | D3: 43832
A4: Indian Rupee | B4: 71.33559 | C4: 0.014018248 | D4: 43831
A5: Indian Rupee | B5: 71.30648 | C5: 0.014023971 | D5: 43830
A6: Indian Rupee | B6: 71.31903 | C6: 0.014021503 | D6: 43829
A7: Indian Rupee | B7: 71.45145 | C7: 0.013995517 | D7: 43826
A8: Indian Rupee | B8: 71.21529 | C8: 0.014041928 | D8: 43825
A9: Indian Rupee | B9: 71.26409 | C9: 0.014032313 | D9: 43824
A10: Indian Rupee | B10: 71.28851 | C10: 0.014027506 | D10: 43823
A11: Indian Rupee | B11: 71.21938 | C11: 0.014041122 | D11: 43822
A12: Indian Rupee | B12: 71.06456 | C12: 0.014071712 | D12: 43819
A13: Indian Rupee | B13: 71.18341 | C13: 0.014048217 | D13: 43818
... A131: Indian Rupee | B131: 68.57479 | C131: 0.014582618 | D131: 43654
A132: Qatari Riyal | B132: 3.63257 | C132: =1/B132 -> 0.27528719 | D132: 43833
A133: Qatari Riyal | B133: 3.64509 | C133: =1/B133 -> 0.27434165 | D133: 43832
A134: Qatari Riyal | B134: 3.6448 | C134: =1/B134 -> 0.27436348 | D134: 43831
A135: Qatari Riyal | B135: 3.64317 | C135: =1/B135 -> 0.27448623 | D135: 43830
A136: Qatari Riyal | B136: 3.63759 | C136: =1/B136 -> 0.27490729 | D136: 43829
A137: Qatari Riyal | B137: 3.63047 | C137: =1/B137 -> 0.27544643 | D137: 43828
A138: Qatari Riyal | B138: 3.63167 | C138: =1/B138 -> 0.27535542 | D138: 43826
A139: Qatari Riyal | B139: 3.64015 | C139: =1/B139 -> 0.27471395 | D139: 43825
A140: Qatari Riyal | B140: 3.63531 | C140: =1/B140 -> 0.2750797 | D140: 43824
A141: Qatari Riyal | B141: 3.63654 | C141: =1/B141 -> 0.27498666 | D141: 43823
A142: Qatari Riyal | B142: 3.63802 | C142: =1/B142 -> 0.27487479 | D142: 43822
A143: Qatari Riyal | B143: 3.64721 | C143: =1/B143 -> 0.27418218 | D143: 43821
... A284: Qatari Riyal | B284: 3.63988 | C284: =1/B284 -> 0.27473433 | D284: 43654

Sheet Asset_Type
A1: Invest_Type | B1: Asset_Type | C1: Asset_Group
A2: FD | B2: In-Hand India | C2: Current
A3: QAR-RD | B3: In-Hand Qatar | C3: Current
A4: MUTUAL FUND | B4: Investment | C4: Current
A5: LIC | B5: Investment | C5: Non-Current
A6: NRE-SBI | B6: In-Hand India | C6: Current
A7: PPF-SBI | B7: Investment | C7: Non-Current
A8: Gold | B8: Investment | C8: Current
A9: NRO-SBI | B9: In-Hand India | C9: Current
A10: SILVER | B10: Investment | C10: Current
A11: SAVING | B11: In-Hand India | C11: Current
A12: FD-SBI | B12: In-Hand India | C12: Current
... A15: STOCKS | B15: Investment | C15: Current

Sheet Budget Processing on Actual
B1: =B5 -> 1 | C1: =C5 -> 2 | D1: =D5 -> 3 | E1: =E5 -> 4 | F1: =F5 -> 5 | G1: =G5 -> 6 | H1: =H5 -> 7 | I1: =I5 -> 8 | ... M1: =M5 -> 12 | P1: Month | Q1: 1 | R1: 2 | S1: 3 | T1: 4 | U1: 5 | V1: 6 | W1: 7 | X1: 8 | Y1: 9 | Z1: 10 | AA1: 11 | AB1: 12 | AC1: TTL
A2: Closing Balance | B2: =B6-SUM(B7:B24) -> 0 | C2: =C6-SUM(C7:C24) -> 0 | D2: =D6-SUM(D7:D24) -> 0 | E2: =E6-SUM(E7:E24) -> 0 | F2: =F6-SUM(F7:F24) -> 0 | G2: =G6-SUM(G7:G24) -> 0 | H2: =H6-SUM(H7:H24) -> 0 | I2: =I6-SUM(I7:I24) -> 0 | ... M2: =M6-SUM(M7:M24) -> -1.0236341e-05 | P2: Closing Balance | Q2: =Q6-Q3 -> 0.029129348 | R2: =R6-R3 -> 0.0028679774 | S2: =S6-S3 -> 0.01514409 | T2: =T6-T3 -> 0.048431084 | U2: =U6-U3 -> 0.017545226 | V2: =V6-V3 -> 0.046087497 | W2: =W6-W3 -> 0.019826127 | X2: =X6-X3 -> 0.032876146 | ... AC2: =AC6-AC3 -> 0.021364961 | AD2: =$AD$6*AC2 -> 7556.0177
A3: Expenditure | B3: =B6-B2 -> 1 | C3: =C6-C2 -> 1 | D3: =D6-D2 -> 1 | E3: =E6-E2 -> 1 | F3: =F6-F2 -> 1 | G3: =G6-G2 -> 1 | H3: =H6-H2 -> 1 | I3: =I6-I2 -> 1 | ... M3: =M6-M2 -> 1.0000102 | P3: Expenditure | Q3: =SUM(Q7:Q24) -> 0.97087065 | R3: =SUM(R7:R24) -> 0.99713202 | S3: =SUM(S7:S24) -> 0.98485591 | T3: =SUM(T7:T24) -> 0.95156892 | U3: =SUM(U7:U24) -> 0.98245477 | V3: =SUM(V7:V24) -> 0.9539125 | W3: =SUM(W7:W24) -> 0.98017387 | X3: =SUM(X7:X24) -> 0.96712385 | ... AC3: =SUM(AC7:AC24) -> 0.97863504 | AD3: =$AD$6*AC3 -> 346107.98
A5: Month | B5: 1 | C5: 2 | D5: 3 | E5: 4 | F5: 5 | G5: 6 | H5: 7 | I5: 8 | J5: 9 | K5: 10 | L5: 11 | M5: 12 | N5: TTL | AD5: 29472
A6: SALARY | B6: 1 | C6: 1 | D6: 1 | E6: 1 | F6: 1 | G6: 1 | H6: 1 | I6: 1 | J6: 1 | K6: 1 | L6: 1 | M6: 1 | N6: =AVERAGE(B6:M6) -> 1 | P6: SALARY | Q6: =IF(B6>0%,($N6+B6)/2,B6) -> 1 | R6: =IF(C6>0%,($N6+C6)/2,C6) -> 1 | S6: =IF(D6>0%,($N6+D6)/2,D6) -> 1 | T6: =IF(E6>0%,($N6+E6)/2,E6) -> 1 | U6: =IF(F6>0%,($N6+F6)/2,F6) -> 1 | V6: =IF(G6>0%,($N6+G6)/2,G6) -> 1 | W6: =IF(H6>0%,($N6+H6)/2,H6) -> 1 | X6: =IF(I6>0%,($N6+I6)/2,I6) -> 1 | ... AB6: =IF(M6>0%,($N6+M6)/2,M6) -> 1 | AC6: =AVERAGE(Q6:AB6) -> 1 | AD6: =AD5*12 -> 353664
A7: RENT | B7: =VLOOKUP($A7,$A$26:$M$43,B$5+1,0) -> 0.32739308 | C7: =VLOOKUP($A7,$A$26:$M$43,C$5+1,0) -> 0.41377962 | D7: =VLOOKUP($A7,$A$26:$M$43,D$5+1,0) -> 0.27105907 | E7: =VLOOKUP($A7,$A$26:$M$43,E$5+1,0) -> 0.37996497 | F7: =VLOOKUP($A7,$A$26:$M$43,F$5+1,0) -> 0.29951406 | G7: =VLOOKUP($A7,$A$26:$M$43,G$5+1,0) -> 0.35486666 | H7: =VLOOKUP($A7,$A$26:$M$43,H$5+1,0) -> 0.24216397 | I7: =VLOOKUP($A7,$A$26:$M$43,I$5+1,0) -> 0.28344945 | ... M7: =VLOOKUP($A7,$A$26:$M$43,M$5+1,0) -> 0.28064975 | N7: =AVERAGE(B7:M7) -> 0.32748241 | P7: RENT | Q7: =IF(B7>0%,($N7+B7)/2,B7) -> 0.32743775 | R7: =IF(C7>0%,($N7+C7)/2,C7) -> 0.37063102 | S7: =IF(D7>0%,($N7+D7)/2,D7) -> 0.29927074 | T7: =IF(E7>0%,($N7+E7)/2,E7) -> 0.35372369 | U7: =IF(F7>0%,($N7+F7)/2,F7) -> 0.31349823 | V7: =IF(G7>0%,($N7+G7)/2,G7) -> 0.34117453 | W7: =IF(H7>0%,($N7+H7)/2,H7) -> 0.28482319 | X7: =IF(I7>0%,($N7+I7)/2,I7) -> 0.30546593 | ... AB7: =IF(M7>0%,($N7+M7)/2,M7) -> 0.30406608 | AC7: =AVERAGE(Q7:AB7) -> 0.32748241 | AD7: =$AD$6*AC7 -> 115818.74
A8: SAVING | B8: =VLOOKUP($A8,$A$26:$M$43,B$5+1,0) -> 0.20063086 | C8: =VLOOKUP($A8,$A$26:$M$43,C$5+1,0) -> 0.16136253 | D8: =VLOOKUP($A8,$A$26:$M$43,D$5+1,0) -> 0.38796622 | E8: =VLOOKUP($A8,$A$26:$M$43,E$5+1,0) -> 0.1676316 | F8: =VLOOKUP($A8,$A$26:$M$43,F$5+1,0) -> 0.34902722 | G8: =VLOOKUP($A8,$A$26:$M$43,G$5+1,0) -> 0.37751772 | H8: =VLOOKUP($A8,$A$26:$M$43,H$5+1,0) -> 0.44899703 | I8: =VLOOKUP($A8,$A$26:$M$43,I$5+1,0) -> 0.40595552 | ... M8: =VLOOKUP($A8,$A$26:$M$43,M$5+1,0) -> 0.20472681 | N8: =AVERAGE(B8:M8) -> 0.254829 | P8: SAVING | Q8: =IF(B8>0%,($N8+B8)/2,B8) -> 0.22772993 | R8: =IF(C8>0%,($N8+C8)/2,C8) -> 0.20809576 | S8: =IF(D8>0%,($N8+D8)/2,D8) -> 0.32139761 | T8: =IF(E8>0%,($N8+E8)/2,E8) -> 0.2112303 | U8: =IF(F8>0%,($N8+F8)/2,F8) -> 0.30192811 | V8: =IF(G8>0%,($N8+G8)/2,G8) -> 0.31617336 | W8: =IF(H8>0%,($N8+H8)/2,H8) -> 0.35191301 | X8: =IF(I8>0%,($N8+I8)/2,I8) -> 0.33039226 | ... AB8: =IF(M8>0%,($N8+M8)/2,M8) -> 0.22977791 | AC8: =AVERAGE(Q8:AB8) -> 0.254829 | AD8: =$AD$6*AC8 -> 90123.843
A9: TRANSFER | B9: =VLOOKUP($A9,$A$26:$M$43,B$5+1,0) -> 0.15823756 | C9: =VLOOKUP($A9,$A$26:$M$43,C$5+1,0) -> 0.11669968 | D9: =VLOOKUP($A9,$A$26:$M$43,D$5+1,0) -> 0.11999537 | E9: =VLOOKUP($A9,$A$26:$M$43,E$5+1,0) -> 0.092793406 | F9: =VLOOKUP($A9,$A$26:$M$43,F$5+1,0) -> 0.065427182 | G9: =VLOOKUP($A9,$A$26:$M$43,G$5+1,0) -> 0.054783214 | H9: =VLOOKUP($A9,$A$26:$M$43,H$5+1,0) -> 0.14876994 | I9: =VLOOKUP($A9,$A$26:$M$43,I$5+1,0) -> 0.20837851 | ... M9: =VLOOKUP($A9,$A$26:$M$43,M$5+1,0) -> 0.15320219 | N9: =AVERAGE(B9:M9) -> 0.14125384 | P9: TRANSFER | Q9: =IF(B9>0%,($N9+B9)/2,B9) -> 0.1497457 | R9: =IF(C9>0%,($N9+C9)/2,C9) -> 0.12897676 | S9: =IF(D9>0%,($N9+D9)/2,D9) -> 0.1306246 | T9: =IF(E9>0%,($N9+E9)/2,E9) -> 0.11702362 | U9: =IF(F9>0%,($N9+F9)/2,F9) -> 0.10334051 | V9: =IF(G9>0%,($N9+G9)/2,G9) -> 0.098018526 | W9: =IF(H9>0%,($N9+H9)/2,H9) -> 0.14501189 | X9: =IF(I9>0%,($N9+I9)/2,I9) -> 0.17481617 | ... AB9: =IF(M9>0%,($N9+M9)/2,M9) -> 0.14722802 | AC9: =AVERAGE(Q9:AB9) -> 0.14125384 | AD9: =$AD$6*AC9 -> 49956.398
A10: WITHDRAW | B10: =VLOOKUP($A10,$A$26:$M$43,B$5+1,0) -> 0.072956675 | C10: =VLOOKUP($A10,$A$26:$M$43,C$5+1,0) -> 0.046103579 | D10: =VLOOKUP($A10,$A$26:$M$43,D$5+1,0) -> 0.093111893 | E10: =VLOOKUP($A10,$A$26:$M$43,E$5+1,0) -> 0 | F10: =VLOOKUP($A10,$A$26:$M$43,F$5+1,0) -> 0.032467648 | G10: =VLOOKUP($A10,$A$26:$M$43,G$5+1,0) -> 0.064717323 | H10: =VLOOKUP($A10,$A$26:$M$43,H$5+1,0) -> 0.029442428 | I10: =VLOOKUP($A10,$A$26:$M$43,I$5+1,0) -> 0.01130509 | ... M10: =VLOOKUP($A10,$A$26:$M$43,M$5+1,0) -> 0.038857149 | N10: =AVERAGE(B10:M10) -> 0.046914755 | P10: WITHDRAW | Q10: =IF(B10>0%,($N10+B10)/2,B10) -> 0.059935715 | R10: =IF(C10>0%,($N10+C10)/2,C10) -> 0.046509167 | S10: =IF(D10>0%,($N10+D10)/2,D10) -> 0.070013324 | T10: =IF(E10>0%,($N10+E10)/2,E10) -> 0 | U10: =IF(F10>0%,($N10+F10)/2,F10) -> 0.039691202 | V10: =IF(G10>0%,($N10+G10)/2,G10) -> 0.055816039 | W10: =IF(H10>0%,($N10+H10)/2,H10) -> 0.038178591 | X10: =IF(I10>0%,($N10+I10)/2,I10) -> 0.029109923 | ... AB10: =IF(M10>0%,($N10+M10)/2,M10) -> 0.042885952 | AC10: =AVERAGE(Q10:AB10) -> 0.044959973 | AD10: =$AD$6*AC10 -> 15900.724
